=========================== short test summary info ============================
ERROR tests/claude/test_claude_compatibility.py
ERROR tests/db/test_db_operations.py - TypeError: Connection() got an unexpected keyword argument 'foreign_keys'
ERROR tests/db_integration/test_db_integration.py - TypeError: Connection() got an unexpected keyword argument 'foreign_keys'
ERROR tests/error_scenarios/test_error_scenarios.py
ERROR tests/integration/test_mcp_integration.py
ERROR tests/models/test_validation.py
ERROR tests/resources/test_resources.py
ERROR tests/tools/test_tools.py
!!!!!!!!!!!!!!!!!!! Interrupted: 8 errors during collection !!!!!!!!!!!!!!!!!!!!
============================== 8 errors in 1.07s ===============================